Workbook

Sheet Corpus
A1: # | B1: Domain — Category | C1: Part | D1: Semantic | E1: English | F1: Character | G1: Mode | H1: Russian | I1: Kazakh
A2: SHAME DOMAIN
A3: 1 | B3: Shame — Moral shame | C3: P1 | D3: caused moral shame, tears as physical manifestation; Ellen (external moral standard, parental authority) | E3: At sixteen, thanks to Mammy and Ellen, she looked sweet, charming and giddy, but she was, in reality, self-willed, vain and obstinate. She had the easily stirred passions of her Irish father and nothing except the thinnest veneer of her mother's unselfish and forbearing nature. Ellen never fully realized that it was only a veneer, for Scarlett always showed her best face to her mother, concealing her escapades, curbing her temper and appearing as sweet-natured as she could in Ellen's presence, for her mother could shame her to tears with a reproachful glance. | F3: Scarlett | G3: felt | H3: TERM: pristydit' (пристыдить) — to put to shame, to shame (someone) [ORD] PASSAGE: ибо одного укоряющего взгляда матери было достаточно, чтобы пристыдить ее до слез. TRANS: ibo odnogo ukoryayushchego vzglyada materi bylo dostatochno, chtoby pristydit' ee do slez. TRANSLATION: for a single reproachful glance from her mother was enough to shame her to tears. | I3: TERM: ŪİALTU (ҰЯЛТУ) — to make (someone) feel ashamed; to disconcert; to embarrass (causative) [KED, SZK] PASSAGE: Өзін момын етіп көрсетудің жолын білді, анасының сөге қараған жалғыз көзқарасы оны ұялтып, жылатуға жеткілікті болатын TRANS: Özın momyn etıp körsetudıñ jolyn bıldı, anasynyñ söge qarağan jalğyz közqarasy ony ūialtyp, jylatuğa jetkılıktı bolatyn TRANSLATION: She knew how to put on an air of meekness; her mother's single reproachful glance was enough to shame her into tears.
A4: 2 | B4: Shame — Moral shame | C4: P1 | D4: mild moral shame, inner accusation; no physical manifestation; Ellen (internalized moral standard) | E4: To Scarlett, the very idea of saying such things to her own mother was almost sacrilegious. And yet—and yet—there was something very pleasant about the Tarleton girls' relations with their mother, and they adored her for all that they criticized and scolded and teased her. Not, Scarlett loyally hastened to tell herself, that she would prefer a mother like Mrs. Tarleton to Ellen, but still it would be fun to romp with a mother. She knew that even that thought was disrespectful to Ellen and felt ashamed of it. | F4: Scarlett | G4: felt | H4: TERM: ustydilas' (устыдилась) — felt ashamed (pf., past fem.) [ORD] (lemma: устыдиться) PASSAGE: Но она устыдилась такой мысли, почувствовав даже в этом какое-то неуважение к Эллин TRANS: No ona ustydilas' takoy mysli, pochuvstvovav dazhe v etom kakoe-to neuvazhenie k Ellin TRANSLATION: But she felt ashamed at such a thought, sensing in it a kind of disrespect toward Ellen | I4: TERM: ŪİALU (ҰЯЛУ) — to feel ashamed; to feel shy; to be embarrassed [KED, SZK] PASSAGE: Әйтсе де мұндай ойдың өзі Эллинге деген құрметсіздік сияқты сезіліп, ұялып қалды. TRANS: Äitse de mūndai oidyñ özı Elinge degen qūrmetsızdık siaqty sezılıp, ūialyp qaldy. TRANSLATION: And yet such a thought itself felt like disrespect toward Ellen, and she felt ashamed.
A5: 3 | B5: Shame — Moral shame | C5: P3 | D5: shame at openly violating social-moral duty; mild; no physical manifestation | E5: She went hastily up the two short blocks to Peachtree Street, breathing the unfouled air in as deep gulps as her tightly laced corset would permit. She was standing on the corner, uncertain as to what she would do next, ashamed to go home to Aunt Pitty's but determined not to go back to the hospital, when Rhett Butler drove by. | F5: Scarlett | G5: felt | H5: TERM: stydno (стыдно) — it is shameful; (one) feels ashamed (impersonal predicate) [ORD] PASSAGE: ей стыдно было возвратиться к тете Питти, TRANS: ey stydno bylo vozvratit'sya k tete Pitti, TRANSLATION: she was ashamed to return to Aunt Pitty, | I5: TERM: ŪİALU (ҰЯЛУ) — to feel ashamed; to feel shy; to be embarrassed [KED, SZK] PASSAGE: Бұрышқа жеткенде әрі қарай қалай жүрерін білмей тұрып қалды; Ол Питти тәтейге баруға ұялды TRANS: Būryşqa jetkende ärı qarai qalai jürerın bılmei tūryp qaldy; Ol Pitti täteige baruğa ūialdy TRANSLATION: When she reached the corner she stood still, not knowing what to do next; she was too ashamed to go to Aunt Pitty.
A6: 4 | B6: Shame — Moral shame | C6: P3 | D6: mild moral shame about angry outburst towards a servant; inner accusation; no physical manifestation; no specific witness | E6: A sullen "Yas'm" drifted up to her and she drew a deep breath, feeling suddenly ashamed of herself. | F6: Scarlett | G6: felt | H6: TERM: ustydyas' (устыдясь) — having felt ashamed (gerund) [ORD] (lemma: устыдиться) PASSAGE: и Скарлетт глубоко вздохнула, устыдясь своей внезапной вспышки TRANS: i Skarlett gluboko vzdokhnula, ustydyas' svoey vnezapnoy vspyshki TRANSLATION: and Scarlett took a deep breath, ashamed of her sudden outburst | I6: TERM: ūialyp (ұялып) — feeling ashamed; embarrassed [KED, SZK] (lemma: ūialu / ұялу — to feel ashamed; to feel shy; to be embarrassed) PASSAGE: Скарлетт өзінің кенеттен тұтанып кеткеніне ұялып, терең күрсінді. TRANS: Skarlett özınıñ kenetten tūtanyp ketkenıne ūialyp, tereñ kürsındı. TRANSLATION: Scarlett, ashamed of her sudden outburst, sighed deeply.
A7: 5 | B7: Shame — Moral shame | C7: P3 | D7: shame about own cowardice, inadvertently exposed by Melanie; no physical manifestation | E7: What Melanie said was no more than Scarlett had been thinking but hearing it put into words infuriated her, shamed her as if her secret cowardice was written plainly in her face. | F7: Scarlett | G7: felt | H7: TERM: stydno (стыдно) — it is shameful; (one) feels ashamed (impersonal predicate) [ORD] PASSAGE: ей было стыдно, словно Мелани прочла трусливые мысли на ее лице. TRANS: ey bylo stydno, slovno Melani prochla truslivye mysli na ee litse. TRANSLATION: she felt ashamed, as if Melanie had read her cowardly thoughts on her face. | I7: TERM: ŪİALU (ҰЯЛУ) — to feel ashamed; to feel shy; to be embarrassed [KED, SZK] PASSAGE: Мелани тек Скарлеттің өзі ойлағанын дауыстап айтқан еді, бірақ Скарлетт, Мелани оның қорқынышын бетінен оқып қойғандай, ұялғаннан ашуланды. TRANS: Melani tek Skarlettıñ özı oilağanyn dauystap aitqan edı, bıraq Skarlett, Melani onyñ qorqynyşyn betınen oqyp qoiğandai, ūialğannan aşulandy. TRANSLATION: Melanie had only said aloud what Scarlett herself had been thinking, but Scarlett, as if Melanie had read her fear on her face, became angry from shame.
A8: 6 | B8: Shame — Moral shame | C8: P3 | D8: shame about unfair inner judgment; no physical manifestation; no audience | E8: By a series of limping jerks, she pulled the body down the hall toward the back porch and, pausing to wipe her forehead with the back of her hand, glanced back toward Melanie, sitting against the wall hugging her thin knees to her bare breasts. How silly of Melanie to be bothering about modesty at a time like this, Scarlett thought irritably. It was just part of her nicey-nice way of acting which had always made Scarlett despise her. Then shame rose in her. After all—after all, Melanie had dragged herself from bed so soon after having a baby and had come to her aid with a weapon too heavy even for her to lift. That had taken courage, the kind of courage Scarlett honestly knew she herself did not possess, the thin-steel, spun-silk courage which had characterized Melanie on the terrible night Atlanta fell and on the long trip home. It was the same intangible, unspectacular courage that all the Wilkeses possessed, a quality which Scarlett did not understand but to which she gave grudging tribute. | F8: Scarlett | G8: felt | H8: TERM: stydno (стыдно) — it is shameful; (one) feels ashamed (impersonal predicate) [ORD] PASSAGE: И тут ей неожиданно стало стыдно. TRANS: I tut ey neozhidanno stalo stydno. TRANSLATION: And then suddenly she felt ashamed. | I8: PASSAGE: Бірақ ол көп ұзамай ұялыс тапты. TRANS: Bıraq ol köp ūzamai ūialys tapty. TRANSLATION: But before long she felt embarrassment / a sense of shame.
A9: 7 | B9: Shame — Moral shame | C9: P4 | D9: shame ascribed to another — performative speech act (verdict / directive) | E9: "She didn't write you? Oh, I guess she was too ashamed to write you. She should be ashamed! Oh, to have such a mean sister!" | F9: Scarlett | G9: ascribed | H9: TERM: stydno (стыдно) — it is shameful; (one) feels ashamed (impersonal predicate) [ORD] PASSAGE: Ах, наверное, ей было слишком стыдно. TRANS: Akh, navernoe, ey bylo slishkom stydno. TRANSLATION: Ah, she must have been too ashamed. | I9: TERM: ŪİAT (ҰЯТ) — shame; disgrace; sense of decency (also: that which is improper) [KED, SZK] PASSAGE: Сірә, ұяты жібермеген шығар. TRANS: Sırä, ūiaty jıbermegen şyğar. TRANSLATION: Most likely shame did not let her [write].
A10: 8 | B10: Shame — Moral shame | C10: P4 | D10: mild shame about being thought better than she is; no physical manifestation; community / diffuse audience | E10: She felt puzzled and a little ashamed, as always when people attributed to her emotions and motives they possessed and thought she shared. | F10: Scarlett | G10: felt | H10: TERM: pristyzhennoy (пристыженной) — shamed, abashed (past pass. participle) [ORD] (lemma: пристыженный) PASSAGE: Скарлетт была озадачена и чувствовала себя немного пристыженной TRANS: Skarlett byla ozadachena i chuvstvovala sebya nemnogo pristyzhennoy TRANSLATION: Scarlett was puzzled and felt herself a bit shamed | I10: TERM: QOLAİSYZ (ҚОЛАЙСЫЗ) — inappropriate; inconvenient; awkward [KED, SZK] PASSAGE: Скарлеттің көңілі алаңдап, өзін қолайсыз сезініп тұр, әйтеуір, адамдар ылғи да бұған өзінің ойлары мен сезімдерін таңады да жүреді, мұның ортақтаспайтынымен шаруалары жоқ. TRANS: Skarlettıñ köñılı alañdap, özın qolaisyz sezınıp tūr, äiteuır, adamdar ylği da būğan özınıñ oilary men sezımderın tañady da jüredı, mūnyñ ortaqtaspaitynymen şarualary joq. TRANSLATION: Scarlett was confused and felt awkward — people always ascribe to her their own thoughts and feelings, with no regard for whether she shares them.
A11: 9 | B11: Shame — Moral shame | C11: P4 | D11: Ashley’s self-directed moral shame about causing another to sacrifice | E11: "You ashamed? Why should you be ashamed? I'm the one to feel shame and I do. If it hadn't been for my stupidity you wouldn't be in this fix. You'd never have married Frank. I should never have let you leave Tara last winter. Oh, fool that I was! I should have known you—known you were desperate, so desperate that you'd— I should have—I should have—" His face went haggard. | F11: Scarlett | G11: ascribed | H11: TERM: stydno (стыдно) — it is shameful; (one) feels ashamed (impersonal predicate) [ORD] PASSAGE: Вам было стыдно? TRANS: Vam bylo stydno? TRANSLATION: You were ashamed? | I11: TERM: ŪİALU (ҰЯЛУ) — to feel ashamed; to feel shy; to be embarrassed [KED, SZK] PASSAGE: Ұялдым дейсіз бе? TRANS: Ūialdym deisız be? TRANSLATION: You say you were ashamed?
A12: 10 | B12: Shame — Moral shame | C12: P4 | D12: moral shame, Ashley’s self-accusation and pain as stimulus; physical manifestation – facial expression (eyes); Ashley as stimulus and witness | E12: The edge in his voice spoke of a raw, unhealed wound that ached within him and his words brought shame to her eyes. He was swift to see it and his face changed to gentleness. | F12: Scarlett | G12: felt | H12: TERM: slezy styda (слезы стыда) — tears of shame [ORD] (lemma: слеза) PASSAGE: Раздражение, звучавшее в его голосе, говорило о незаживающей ране, которая болела, и от его слов слезы стыда выступили у нее на глазах. TRANS: Razdrazhenie, zvuchavshee v ego golose, govorilo o nezazhivayushchey rane, kotoraya bolela, i ot ego slov slezy styda vystupili u nee na glazakh. TRANSLATION: The irritation that sounded in his voice spoke of an unhealing wound that hurt, and at his words tears of shame welled up in her eyes. | I12: PASSAGE: Эшлидің үнінде бір наланың белгісі бар секілді, жазылмаған жараның қазір де жанына батып тұрғаны байқалғанда, Скарлеттің көзінен жас тамшылары ытқып шығып, кеудесіне тырс-тырс тамды. TRANS: Eşlidıñ ünınde bır nalanyñ belgısı bar sekıldı, jazylmağan jaranyñ qazır de janyna batyp tūrğany baiqalğanda, Skarlettıñ közınen jas tamşylary ytqyp şyğyp, keudesıne tyrs-tyrs tamdy. TRANSLATION: In Ashley's voice there was, as it were, a sign of grievance — it could be felt that the unhealed wound was hurting his soul even now — and tears of shame burst from Scarlett's eyes and dripped onto her chest.
A13: 11 | B13: Shame — Moral shame | C13: P4 | D13: moral shame, inner accusation; no physical manifestation; not understanding Melanie as stimulus and moral mirror; Melanie ascribing noble motives to Scarlett when she had ulterior motives | E13: Her eyes blazed with enthusiasm and happiness and the two stared at her, Ashley with a queer stunned look, Scarlett with surprise mingled with shame. It had never occurred to her that Melanie missed Atlanta so much and longed to be back, longed for a home of her own. She had seemed so contented at Tara it came to Scarlett as a shock that she was homesick. | F13: Scarlett | G13: felt | H13: TERM: styda (стыда) — shame (genitive) [ORD] (lemma: стыд) PASSAGE: Скарлетт — со смесью удивления и стыда. TRANS: Skarlett — so smes'yu udivleniya i styda. TRANSLATION: Scarlett — with a mix of surprise and shame. | I13: TERM: ŪİAT(ҰЯТ) — shame; disgrace; sense of decency (also: that which is improper) [KED, SZK] PASSAGE: Эшли дағдарып, есін жия алмаса, Скарлетт ұяттан өртеніп әрі таңырқап тұр. TRANS: Eşli dağdaryp, esın jia almasa, Skarlett ūiattan örtenıp ärı tañyrqap tūr. TRANSLATION: While Ashley was confused and could not collect himself, Scarlett stood burning with shame and astonished.
A14: 12 | B14: Shame — Moral shame | C14: P4 | D14: moral shame, inner accusation; no physical manifestation; Melanie as moral mirror; Melanie and Ashley audience | E14: As usual when confronted by Melanie's habit of attributing worthy motives where no worth existed, Scarlett was ashamed and irritated, and suddenly she could not meet either Ashley's or Melanie's eyes. | F14: Scarlett | G14: felt | H14: TERM: styda (стыда) — shame (genitive) [ORD] (lemma: стыд) PASSAGE: И Скарлетт, столкнувшись с этим умением Мелани приписывать людям благородные поступки там, где благородством и не пахло, почувствовала, по обыкновению, прилив стыда и раздражения TRANS: I Skarlett, stolknuvshis' s etim umeniem Melani pripisyvat' lyudyam blagorodnye postupki tam, gde blagorodstvom i ne pakhlo, pochuvstvovala, po obyknoveniyu, priliv styda i razdrazheniya TRANSLATION: And Scarlett, faced with this skill of Melanie's for ascribing noble motives to people where no nobility was to be found, felt her customary surge of shame and irritation | I14: TERM: ŪİAT (ҰЯТ) — shame; disgrace; sense of decency (also: that which is improper) [KED, SZK] PASSAGE: Өзінің көрген, маңдайына бұйырған әр жақсылығын қашан да біреудің арқасында болды деп ойлайтын Меланидің мына қуанышты күйі Скарлеттің бетінен отын шығарып, ұяттан жерге кірердей болды. TRANS: Özınıñ körgen, mañdaiyna būiyrğan är jaqsylyğyn qaşan da bıreudıñ arqasynda boldy dep oilaityn Melanidıñ myna quanyşty küiı Skarlettıñ betınen otyn şyğaryp, ūiattan jerge kırerdei boldy. TRANSLATION: Melanie's joyous mood — always thinking that every good thing she had received in life had come because of someone else — made Scarlett's face burn and want to sink into the ground from shame.
... A24: 22 | B24: Shame — Moral shame | C24: P4 | D24: Moral shame observed by Scarlett | E24: Ashley was doing little better with convicts than he had done with free labor, although why, he was unable to tell. Moreover, he looked as if he were ashamed to be working convicts and he had little to say to her these days. | F24: Ashley | G24: felt | H24: TERM: stydilsya (стыдился) — felt ashamed (3sg masc. past, impf.) [ORD] (lemma: стыдиться) PASSAGE: К тому же он, казалось, стыдился того, что у него работают каторжники, и почти не общался со Скарлетт. TRANS: K tomu zhe on, kazalos', stydilsya togo, chto u nego rabotayut katorzhniki, i pochti ne obshchalsya so Skarlett. TRANSLATION: Moreover, he seemed to be ashamed that convicts were working for him, and he hardly communicated with Scarlett at all. | I24: TERM: QYSYLU (ҚЫСЫЛУ) — to feel embarrassed; to feel constrained; to be in difficulty [KED, SZK] PASSAGE: Сотталғандармен жұмыс істеп жүргеніне қысылатын да сияқты ма, Скарлеттпен де көп кездеспей жүр. TRANS: Sottalğandarmen jūmys ıstep jürgenıne qysylatyn da siaqty ma, Skarlettpen de köp kezdespei jür. TRANSLATION: It seems he is also embarrassed at working with convicts; he no longer often meets with Scarlett either.
A25: 23 | B25: Shame — Moral shame | C25: P5 | E25: And, for the first time, some of the bright glow which had enveloped him since the first day she fell in love with him began to fade imperceptibly. The tarnish of shame and guilt that enveloped her spread to him as well. Resolutely she tried to fight off this thought but it only made her cry harder. | F25: Scarlett-Ashley | G25: felt | H25: TERM: pozor (позор) — disgrace; shame; ignominy [ORD] PASSAGE: Черное пятно позора и вины, лежавшее на ней, переползло и на него. TRANS: Černoe pjatno pozora i viny, ležavšee na nej, perepolzlo i na nego. TRANSLATION: The black stain of disgrace and guilt that lay upon her spread to him as well. | I25: TERM: kınä men künä (кінә мен күнә) — guilt and sin (set phrase combining secular and religious registers) [KED, SZK] (lemma: кінә) PASSAGE: Осы уақытқа дейін өз арқасына басқан кінә мен күнәнің қап-қара нүктесі жылыстап, Эшлиге қарай ауып бара жатты. TRANS: Osy uaqytqa deiın öz arqasyna basqan kınä men künänıñ qap-qara nüktesı jylystap, Eşlige qarai auyp bara jatty. TRANSLATION: Up till now, the pitch-black mark of guilt and sin she had borne on her own back was sliding off and shifting toward Ashley.
A26: 24 | B26: Shame — Moral shame | C26: P3 | D26: Shame about being caught in a lie about knowing midwifery | E26: "Fo' Gawd, Miss Scarlett—" Fright and shame were in her rolling eyes. | F26: Prissy | G26: felt | H26: TERM: styd (стыд) — shame; the feeling of having transgressed a moral or social norm [ORD] PASSAGE: Растерянность и стыд были в ее вытаращенных от страха глазах. TRANS: Rasteryannost' i styd byli v ee vytarashchennykh ot strakha glazakh. TRANSLATION: Bewilderment and shame were in her eyes bulging with terror. | I26: TERM: ŪİALU (ҰЯЛУ) — to feel ashamed; to feel shy; to be embarrassed [KED, SZK] PASSAGE: Оның жүзінен абыржу мен ұялғандықты анық бауқауға болатын еді. TRANS: Onyñ jüzınen abyrju men ūialğandyqty anyq bauqauğa bolatyn edı. TRANSLATION: Bewilderment and shame could be clearly seen on her face.
A27: 25 | B27: Shame — Moral shame | C27: P3 | D27: Potential moral shame about spending money when he could steal | E27: She had a shrewd suspicion that the reason he had so much money left over was that he had not bought the fowls or most of the food. Pork would have taken shame to himself had he spent her money when there were unguarded hen coops along the road and smokehouses handy. | F27: Pork | G27: felt | H27: TERM: posramil by samogo sebya (посрамил бы самого себя) — would have brought shame on himself [ORD] (lemma: посрамить) PASSAGE: Порк посрамил бы самого себя, если бы потратил ее деньги TRANS: Pork posramil by samogo sebya, esli by potratil ee den'gi TRANSLATION: Pork would have shamed himself if he had spent her money | I27: PASSAGE: Скарлетт берген ақшаны жұмсаса, Порк өзін-өзі кешірмес еді. TRANS: Skarlett bergen aqşany jūmsasa, Pork özın-özı keşırmes edı. TRANSLATION: If he had spent the money Scarlett gave him, Pork would not forgive himself.
A28: 26 | B28: Shame — Absent moral shame | C28: P2 | D28: moral conventions breached — manipulation, lies; shame ABSENT | E28: Scarlett turned and tiptoed through the silent hall into the dining room to get the brandy bottle that she and Melly privately called the "swoon bottle" because Pittypat always took a sip from it when her fluttering heart made her faint—or seem to faint. Triumph was written on her face and no trace of shame for her unfilial treatment of Gerald. Now Ellen would be soothed with lies if any other busybody wrote her. Now she could stay in Atlanta. Now she could do almost as she pleased, Pittypat being the weak vessel that she was. She unlocked the cellaret and stood for a moment with the bottle and glass pressed to her bosom. | F28: Scarlett | G28: felt | H28: TERM: nikakikh ugryzeniy sovesti (никаких угрызений совести) — no pangs of conscience whatsoever [ORD] (lemma: угрызение) PASSAGE: Лицо Скарлетт выражало торжество — никаких угрызений совести она не испытывала, хотя и поступила с Джералдом отнюдь не как любящая, преданная дочь. TRANS: Litso Skarlett vyrazhalo torzhestvo — nikakikh ugryzeniy sovesti ona ne ispytyvala, khotya i postupila s Dzheraldom otnyud' ne kak lyubyashchaya, predannaya doch'. TRANSLATION: Scarlett's face wore a triumphant expression — she felt no pangs of conscience whatsoever, although she had not behaved like a loving, devoted daughter toward Gerald. | I28: TERM: QYMSYNU (ҚЫМСЫНУ) — to feel awkward; to feel embarrassed [KED, SZK] PASSAGE: Скарлеттің бет-әлпетінде жеңіске жеткен түр байқалады, ол Джералдқа әкесін жақсы көретін адал қызы емес, бөтен біреудей қулық жасағанына еш қымсынған жоқ. TRANS: Skarlettıñ bet-älpetınde jeñıske jetken tür baiqalady, ol Jeraldqa äkesın jaqsy köretın adal qyzy emes, böten bıreudei qulyq jasağanyna eş qymsynğan joq. TRANSLATION: Scarlett's face showed a victorious expression; she felt no embarrassment at all that she had played a trick on Gerald like a stranger rather than as a loving, faithful daughter.
A29: 27 | B29: Shame — Absent moral shame | C29: P4 | D29: moral and social conventions breached — shame ABSENT; Ashley as witness | E29: She was still clutching the ball of red clay when she went up the front steps. She had carefully avoided the back entrance, for Mammy's sharp eyes would certainly have seen that something was greatly amiss. Scarlett did not want to see Mammy or anyone else. She did not feel that she could endure seeing anyone or talking to anyone again. She had no feeling of shame or disappointment or bitterness now, only a weakness of the knees and a great emptiness of heart. She squeezed the clay so tightly it ran out from her clenched fist and she said over and over, parrot-like: "I've still got this. Yes, I've still got this." | F29: Scarlett | G29: felt | H29: TERM: styd (стыд) — shame; the feeling of having transgressed a moral or social norm [ORD] PASSAGE: Ее уже не мучил стыд, разочарование или горечь — лишь была какая-то слабость в коленях да огромная пустота в душе. TRANS: Ee uzhe ne muchil styd, razocharovanie ili gorech' — lish' byla kakaya-to slabost' v kolenyakh da ogromnaya pustota v dushe. TRANSLATION: She was no longer tormented by shame, disappointment, or bitterness — only a kind of weakness in her knees and a vast emptiness in her soul. | I29: TERM: ŪİAT (ҰЯТ) — shame; disgrace; sense of decency (also: that which is improper) [KED, SZK] PASSAGE: Қалған көңіл де, қысқан ұят та бір шетке ысырылып, жан дүниесі босап, буын-буынынан әл кетіпті. TRANS: Qalğan köñıl de, qysqan ūiat ta bır şetke ysyrylyp, jan düniesı bosap, buyn-buynynan äl ketıptı. TRANSLATION: Both her remaining feelings and her gripping shame had been pushed aside; her inner being was emptied, and the strength had left her every joint.
A30: 28 | B30: Shame — Absent moral shame | C30: P5 | D30: Immoral behavior impossible with Rhett as specific witness | E30: Already she was regretting the hasty words. Had they been spoken to anyone save Rhett she would have shamelessly retracted them. Why had she burst out like that? She looked at Rhett with an angry frown and saw that he was watching her with his old keen, cat-at-a- mouse-hole look. When he saw her frown, he laughed suddenly, his white teeth flashing. Scarlett had an uncertain feeling that he had jockeyed her into this position. | F30: Scarlett | G30: felt | H30: TERM: stesneniya (стеснения) — awkwardness; constraint (gen.) [ORD] (lemma: стеснение) PASSAGE: Скажи она их кому угодно, кроме Ретта, она бы без всякого стеснения взяла их назад. TRANS: Skazhi ona ikh komu ugodno, krome Retta, ona by bez vsyakogo stesneniya vzyala ikh nazad. TRANSLATION: Had she said it to anyone but Rhett, she would have taken it back without any embarrassment. | I30: PASSAGE: Мұның бәрін кімге айтқан болса да, кейін қайтарып ала салар еді, айтқанынан қайта танар еді, тек Реттің алдында емес. TRANS: Mūnyñ bärın kımge aitqan bolsa da, keiın qaitaryp ala salar edı, aitqanynan qaita tanar edı, tek Rettıñ aldynda emes. TRANSLATION: Whoever she had said all this to, she would have taken it back, would have recanted — except in front of Rhett.
A31: 29 | B31: Shame — Absent social shame (about the body) | C31: P1 | D31: body confidence: NO shame about body as social object | E31: Of course, her brooch could be pinned over the spot, but perhaps Melanie had sharp eyes. There remained varicolored cotton dresses which Scarlett felt were not festive enough for the occasion, ball dresses and the green sprigged muslin she had worn yesterday. But it was an afternoon dress. It was not suitable for a barbecue, for it had only tiny puffed sleeves and the neck was low enough for a dancing dress. But there was nothing else to do but wear it. After all she was not ashamed of her neck and arms and bosom, even if it was not correct to show them in the morning. | F31: Scarlett | G31: felt | H31: TERM: stydit'sya (стыдиться) — to feel ashamed (imperfective); pf. постыдиться/устыдиться [ORD] PASSAGE: ей не приходится стыдиться TRANS: ey ne prikhoditsya stydit'sya TRANSLATION: she did not have to feel ashamed | I31: TERM: QYSYLU (ҚЫСЫЛУ) — to feel embarrassed; to feel constrained; to be in difficulty [KED, SZK] PASSAGE: Түптеп келгенде тіпті таңертеңнен мойнын, иығын, қолын жаңалаштау аса орынды болмаса да, сол үшін қысылуына тура келмейді. TRANS: Tüptep kelgende tıptı tañerteñnen moinyn, iyğyn, qolyn jañalaştau asa oryndy bolmasa da, sol üşın qysyluyna tura kelmeidı. TRANSLATION: After all, even though baring her neck, shoulders, and arms in the morning was not entirely proper, she did not have to feel embarrassed about it.
A32: 30 | B32: Shame — Absent social shame (about the body) | C32: P1 | D32: body confidence: NO shame about body as social object | E32: As she stood before the mirror and twisted herself about to get a side view, she thought that there was absolutely nothing about her figure to cause her shame. Her neck was short but rounded and her arms plump and enticing. Her breasts, pushed high by her stays, were very nice breasts. | F32: Scarlett | G32: felt | H32: TERM: iz"yana (изъяна) — defect; flaw (gen.) [ORD] (lemma: изъян) PASSAGE: не обнаружила в своей фигуре ни малейшего изъяна. TRANS: ne obnaruzhila v svoey figure ni maleyshego iz"yana. TRANSLATION: she found not the slightest flaw in her figure. | I32: TERM: KEMŞILIK (КЕМШІЛІК) — defect; failing; shortcoming [KED, SZK] PASSAGE: Айна алдында тұрып, ол өзін жанынан көру үшін белін майыстырып қарап, сымбатынан еш кемшілік таппады. comment: 'shame' is not directly translated. TRANS: Aina aldynda tūryp, ol özın janynan köru üşın belın maiystyryp qarap, symbatynan eş kemşılık tappady. comment: 'shame' is not directly translated. TRANSLATION: Standing before the mirror and turning sideways to view her profile, she found no flaw in her elegance.
A33: 31 | B33: Shame — Social shame | C33: P1 | D33: strong shame about social convention and exposure to societal judgment; internal burning | E33: She did not want to be fair, although she knew what he said was true. He had never once crossed the borders of friendliness with her and, when she thought of this fresh anger rose, the anger of hurt pride and feminine vanity. She had run after him and he would have none of her. He preferred a whey-faced little fool like Melanie to her. Oh, far better that she had followed Ellen and Mammy's precepts and never, never revealed that she even liked him—better anything than to be faced with this scorching shame! | F33: Scarlett | G33: felt | H33: TERM: sgorat' so styda (сгорать со стыда) — to burn up with shame (idiom) [ORD] (lemma: сгорать) PASSAGE: Пусть бы он никогда-никогда не узнал об этом — все лучше, чем так сгорать со стыда TRANS: Pust' by on nikogda-nikogda ne uznal ob etom — vse luchshe, chem tak sgorat' so styda TRANSLATION: Let him never, never know about it — anything would be better than burning up with shame so | I33: TERM: ŪİAT (ҰЯТ) — shame; disgrace; sense of decency (also: that which is improper) [KED, SZK] PASSAGE: Ах, ол неге Эллин мен Үлкен шешейдің нұсқауын тыңдамады! Эшли мұның сезімінен күдіктенбеуі керек еді! Бұлай ұяттан өртенгенше, оның бұл туралы ешқашан, еш уақытта білмегені жақсы еді! TRANS: Ah, ol nege Elin men Ülken şeşeidıñ nūsqauyn tyñdamady! Eşli mūnyñ sezımınen küdıktenbeuı kerek edı! Būlai ūiattan örtengenşe, onyñ būl turaly eşqaşan, eş uaqytta bılmegenı jaqsy edı! TRANSLATION: Ah, why had she not heeded Ellen's and Mammy's instructions! Ashley should not have suspected her feelings! Better that he should never, ever know about this than to burn up like this with shame!
A34: 32 | B34: Shame — Social shame (somatic expression) | C34: P2 | D34: strong shame about breaking social conventions and Ashley’s rejection, social exposure, physical manifestations – face crimson; Rhett witness | E34: She looked up at him imploringly, her face crimson with the shame of their last meeting, and met two of the blackest eyes she had ever seen, dancing in merciless merriment. Of all the people in the world to turn up here, this terrible person who had witnessed that scene with Ashley which still gave her nightmares; this odious wretch who ruined girls and was not received by nice people; this despicable man who had said, and with good cause, that she was not a lady. | F34: Scarlett | G34: felt | H34: TERM: Zardevshis' ot smushcheniya, (Зардевшись от смущения,) = flushing; having blushed PASSAGE: Зардевшись от смущения, она с мольбой подняла на него глаза TRANS: Zardevshis' ot smushcheniya, ona s mol'boy podnyala na nego glaza TRANSLATION: Burning crimson with embarrassment, she raised her eyes pleadingly to him | I34: TERM: ŪİALU (ҰЯЛУ) — to feel ashamed; to feel shy; to be embarrassed [KED, SZK] PASSAGE: Ұяла қысылған Скарлетт оған басын көтеріп қарады, ... TRANS: Ūiala qysylğan Skarlett oğan basyn köterıp qarady, ... TRANSLATION: Scarlett, flushed with embarrassment, raised her head and looked at him,...
A35: 33 | B35: Shame — Social shame | C35: P2 | D35: shame at absence of social tokens of pride (comparison) | E35: She flipped back the edges of the letters, looking at the dates, remembering their contents. In them there were no fine descriptive pages of bivouacs and charges such as Darcy Meade wrote his parents or poor Dallas McLure had written his old-maid sisters, Misses Faith and Hope. The Meades and McLures proudly read these letters all over the neighborhood, and Scarlett had frequently felt a secret shame that Melanie had no such letters from Ashley to read aloud at sewing circles. | F35: Scarlett | G35: felt | H35: TERM: styd (стыд) — shame; the feeling of having transgressed a moral or social norm [ORD] PASSAGE: Скарлетт не раз испытывала втайне стыд, что Эшли не пишет Мелани таких писем, которые интересно было бы почитать в швейном кружке вслух. TRANS: Skarlett ne raz ispytyvala vtayne styd, chto Eshli ne pishet Melani takikh pisem, kotorye interesno bylo by pochitat' v shveynom kruzhke vslukh. TRANSLATION: Scarlett had more than once felt secret shame that Ashley did not write Melanie letters of the kind that would be interesting to read aloud in the sewing circle. | I35: TERM: ŪİALU (ҰЯЛУ) — to feel ashamed; to feel shy; to be embarrassed [KED, SZK] PASSAGE: ... ал Скарлетт Эшлидің Меланиге мұндай хаттарды жазбағанына бірнеше рет ішінен ұялған, ... TRANS: ... al Skarlett Eşlidıñ Melanige mūndai hattardy jazbağanyna bırneşe ret ışınen ūialğan, ... TRANSLATION: ...and Scarlett had felt ashamed inwardly several times that Ashley did not write Melanie such letters,...
A36: 34 | B36: Shame — Social shame (somatic expression) | C36: P3 | D36: strong shame about breaking social-moral conventions, social exposure, face crimson; Ellen (internalized moral standard); Rhett as witness | E36: Scarlett leaped to her feet, her face red with shame. How could she have said such a thing! How could she, Ellen's daughter, with her upbringing, have sat there and listened to such debasing words and then made such a shameless reply? She should have screamed. She should have fainted. She should have turned coldly away in silence and swept from the porch. Too late now! | F36: Scarlett | G36: felt | H36: TERM: sgoraya ot styda. (сгорая от стыда.) = burning with shame PASSAGE: Скарлетт вскочила с кресла, сгорая от стыда. TRANS: Skarlett vskochila s kresla, sgoraya ot styda. TRANSLATION: Scarlett leapt up from the chair, burning with shame. | I36: TERM: ŪİAT (ҰЯТ) — shame; disgrace; sense of decency (also: that which is improper) [KED, SZK] PASSAGE: Скарлетт ұяттан өртеніп креслодан атып тұрды. TRANS: Skarlett ūiattan örtenıp kreslodan atyp tūrdy. TRANSLATION: Scarlett, burning up with shame, sprang up from the armchair.
A37: 35 | B37: Shame — Social shame | C37: P4 | D37: Deferred shame from self-humiliation through social-moral transgression; Rhett witness | E37: When he had hurried away to bring her a glass of wine and a paper thin slice of cake, Scarlett sat down in the alcove at the end of the drawing room and carefully arranged her skirts so that the worst spots would not show. The humiliating events of the morning with Rhett were pushed from her mind by the excitement of seeing so many people and hearing music again. Tomorrow she would think of Rhett's conduct and her shame and they would make her writhe again. Tomorrow she would wonder if she had made any impression on Frank's hurt and bewildered heart. But not tonight. Tonight she was alive to her finger tips, every sense alert with hope, her eyes sparkling. | F37: Scarlett | G37: felt | H37: TERM: unizhenii (унижении) — humiliation (prep.) [ORD] (lemma: унижение) PASSAGE: Завтра она снова будет думать о поведении Ретта, о своем унижении и снова будет кипеть от гнева. TRANS: Zavtra ona snova budet dumat' o povedenii Retta, o svoem unizhenii i snova budet kipet' ot gneva. TRANSLATION: Tomorrow she would once again be thinking of Rhett's behavior, of her humiliation, and would once again be seething with anger. | I37: TERM: QYSAS (ҚЫСАС) — malice; revenge; spite [KED, SZK] PASSAGE: Ертең Реттің қылығын қайтадан еске түсіріп, өзіне жасаған қысастығына күйініп, тағы да ашудан қызынатын шығар. TRANS: Erteñ Rettıñ qylyğyn qaitadan eske tüsırıp, özıne jasağan qysastyğyna küiınıp, tağy da aşudan qyzynatyn şyğar. TRANSLATION: Tomorrow she would probably again recall Rhett's behavior, again be wounded by the wrong he had done her, and again burn with anger.
... A106: 104 | B106: Shame — Performed / ironic shame | C106: P5 | D106: shame PERFORMED — not genuinely felt | E106: "Somehow," said Mrs. Elsing uncertainly, "somehow, I don't think he's so bad. A man who fought for the Confederacy can't be all bad. It's Scarlett who is the bad one. Do you know, Dolly, I really believe that he—well, he's ashamed of Scarlett but is too much of a gentleman to let on." | F106: Rhett | G106: ascribed | H106: TERM: styditsya (стыдится) — feels ashamed (3sg) [ORD] (lemma: стыдиться) PASSAGE: Знаете, Долли, мне в самом деле кажется, что он… ну, словом, что он стыдится Скарлетт, но, будучи джентльменом, не показывает этого. TRANS: Znaete, Dolli, mne v samom dele kazhetsya, chto on… nu, slovom, chto on styditsya Skarlett, no, buduchi dzhentl'menom, ne pokazyvaet etogo. TRANSLATION: You know, Dolly, it really seems to me that he... well, that he is ashamed of Scarlett, but being a gentleman, he does not show it. | I106: TERM: ŪİALU (ҰЯЛУ) — to feel ashamed; to feel shy; to be embarrassed [KED, SZK] PASSAGE: Байқайсыз ба, Долли, сірә, ол Скарлетт үшін ұялатын тәрізді ме, қалай? Тек онысын байқатпайтын сияқты. Қанша дегенмен мырза емес пе? TRANS: Baiqaisyz ba, Dolli, sırä, ol Skarlett üşın ūialatyn tärızdı me, qalai? Tek onysyn baiqatpaityn siaqty. Qanşa degenmen myrza emes pe? TRANSLATION: Don't you notice, Dolly — it seems perhaps he is ashamed for Scarlett's sake, no? But he doesn't let it show. After all, isn't he a gentleman?
A107: GUILT DOMAIN
A108: 105 | B108: Guilt — Felt guilt | C108: P1 | D108: strong felt guilt; inner moral accusation; presence of the person wronged actualizes felt guilt | E108: Since the day of the speaking, Stuart had been uncomfortable in India's presence. Not that India ever reproached him or even indicated by look or gesture that she was aware of his abruptly changed allegiance. She was too much of a lady. But Stuart felt guilty and ill at ease with her. He knew he had made India love him and he knew that she still loved him and, deep in his heart, he had the feeling that he had not played the gentleman. | F108: Stuart Tarleton | G108: felt | H108: TERM: chuvstva viny (чувства вины) — feeling of guilt (gen.) [ORD] (lemma: вина) PASSAGE: Но Стюарт не мог избавиться от чувства вины и испытывал поэтому неловкость. TRANS: No Styuart ne mog izbavit'sya ot chuvstva viny i ispytyval poetomu nelovkost'. TRANSLATION: But Stuart could not rid himself of the feeling of guilt and as a result felt awkward. | I108: TERM: KİNÄLY (КІНӘЛЫ) — guilty; at fault [KED, SZK] (lemma: кінәлі) PASSAGE: Бірақ Стюарт оның алдында өзін кінәлі сезінгендіктен ыңғайсыздықтан арыла алмады. TRANS: Biraq Styuart onyñ aldynda özin kinäli sezingendikten yñğaysyzdyqtan aryla almady. TRANSLATION: But Stuart could not rid himself of the awkwardness of feeling guilty before her.
A109: 106 | B109: Guilt — Felt guilt (guilty pleasure) | C109: P1 | D109: mild guilty pleasure — impropriety felt as pleasurable; no moral weight; Ellen as superego | E109: Scarlett had no awe of her father and felt him more her contemporary than her sisters, for jumping fences and keeping it a secret from his wife gave him a boyish pride and guilty glee that matched her own pleasure in outwitting Mammy. She rose from her seat to watch him. | F109: Gerald O’Hara | G109: felt | H109: PASSAGE: Он был как бы ее сверстником — даже больше, чем сестры, — ведь Джералд, словно мальчишка, любил втайне от жены скакать по полям напрямик, а Скарлетт — тоже большая охотница до всяких эскапад — была его верной союзницей против Мамушки. TRANS: On byl kak by ee sverstnikom — dazhe bol'she, chem sestry, — ved' Dzherald, slovno mal'chishka, lyubil vtayne ot zheny skakat' po polyam napryamik, a Skarlett — tozhe bol'shaya okhotnitsa do vsyakikh eskapad — byla ego vernoy soyuznitsey protiv Mamushki. TRANSLATION: He was, as it were, her contemporary — even more so than her sisters — for Gerald, like a boy, loved to gallop straight across the fields out of his wife's sight, and Scarlett — herself a great enthusiast of escapades — was his loyal ally against Mammy. | I109: PASSAGE: - TRANS: - TRANSLATION: -
A110: 107 | B110: Guilt — Felt guilt | C110: P1 | D110: strong felt guilt; inner moral accusation; Ellen (internalized superego) | E110: "Ah-ah-hum," said Gerald, suddenly and guiltily aware that the conversation, a most interesting and entirely proper one to him, would seem quite otherwise to Ellen. In fact, he knew she would never recover should she learn that her daughters had been exposed to so frank a conversation. But Mrs. Tarleton was, as usual, deaf to all other ideas when pursuing her favorite topic, breeding, whether it be horses or humans. | F110: Gerald O’Hara | G110: felt | H110: TERM: smushchenno (смущенно) — in embarrassment; awkwardly (adv.) [ORD] PASSAGE: — Хм, да, да, — смущенно пробормотал Джералд, до сознания которого вдруг дошло, что этот чрезвычайно интересный и вполне, на его взгляд, приличный разговор, вероятно, показался бы совсем неуместным его жене TRANS: — Khm, da, da, — smushchenno probormotal Dzherald, do soznaniya kotorogo vdrug doshlo, chto etot chrezvychayno interesnyy i vpolne, na ego vzglyad, prilichnyy razgovor, veroyatno, pokazalsya by sovsem neumestnym ego zhene TRANSLATION: "Hm, yes, yes," Gerald muttered in embarrassment, suddenly realizing that this conversation, extremely interesting and, in his view, perfectly proper, would probably appear utterly inappropriate to his wife | I110: TERM: ŪİALU (ҰЯЛУ) — to feel ashamed; to feel shy; to be embarrassed [KED, SZK] PASSAGE: ... Джералд ұялғаннан күбірлеп, ол кенет өзінің ойынша өте қызықты әрі әжептәуір әңгіме әйеліме мүлдем орынсыз болып көрінер еді деп ойлады. TRANS: ... Jerald ūialğannan kübırlep, ol kenet özınıñ oiynşa öte qyzyqty ärı äjeptäuır äñgıme äielıme müldem orynsyz bolyp körıner edı dep oilady. TRANSLATION: ... Gerald murmured in embarrassment, suddenly thinking that the conversation he found very interesting and respectable would seem entirely improper to his wife.
A111: 108 | B111: Guilt — Felt guilt (guilty pleasure) | C111: P1 | D111: mild guilty pleasure — relief mixed with guilt about feeling relief at the absence of her moral superego (Ellen) and her social conscience (Mammy) | E111: As the carriage bore her down the red road toward the Wilkes plantation, Scarlett had a feeling of guilty pleasure that neither her mother nor Mammy was with the party. There would be no one at the barbecue who, by delicately lifted brows or out-thrust underlip, could interfere with her plan of action. | F111: Scarlett | G111: felt | H111: TERM: ne bez nekotorykh ugryzeniy sovesti (не без некоторых угрызений совести) — not without some pangs of conscience [ORD] (lemma: угрызение) PASSAGE: Пока коляска, поднимая красную пыль, катилась по дороге к Двенадцати Дубам, Скарлетт, не без некоторых угрызений совести, радовалась тому, что ни Эллин, ни Мамушка не будут присутствовать на барбекю. TRANS: Poka kolyaska, podnimaya krasnuyu pyl', katilas' po doroge k Dvenadtsati Dubam, Skarlett, ne bez nekotorykh ugryzeniy sovesti, radovalas' tomu, chto ni Ellin, ni Mamushka ne budut prisutstvovat' na barbekyu. TRANSLATION: As the carriage rolled along the road to Twelve Oaks raising red dust, Scarlett, not without some pangs of conscience, was glad that neither Ellen nor Mammy would be present at the barbecue. | I111: TERM: AR (АР) — honour; conscience; inalienable inner moral principle [KED, SZK] PASSAGE: Скарлетт аздап ары мазаласа да, барбекюде Эллиннің де, Үлкен шешейдің де болмайтынына қуанды. TRANS: Skarlett azdap ary mazalasa da, barbeküde Elinnıñ de, Ülken şeşeidıñ de bolmaitynyna quandy TRANSLATION: Although Scarlett's conscience troubled her a little, she rejoiced that neither Ellen nor Mammy would be at the barbecue.
A112: 109 | B112: Guilt — Guilt as tormentor | C112: P2 | D112: felt guilt; inner moral accusation; Ellen (internalized superego); guilt about Ellen’s pain, not about scandalous conduct | E112: A cold qualm of guilt assailed Scarlett at the thought of Ellen's consternation, should she ever learn of her daughter's scandalous conduct. But she took heart at the thought of the twenty-five miles between Atlanta and Tara. Miss Pitty certainly wouldn't tell Ellen. It would put her in such a bad light as a chaperon. And if Pitty didn't tattle, she was safe. | F112: Scarlett | G112: felt | H112: TERM: raskayanie (раскаяние) — repentance; remorse [ORD] PASSAGE: Скарлетт похолодела и в душе у нее пробудилось раскаяние. TRANS: Skarlett pokholodela i v dushe u nee probudilos' raskayanie. TRANSLATION: Scarlett went cold and remorse awakened in her soul. | I112: TERM: ÖKİNİSH (ӨКІНІШ) — regret; repentance [KED, SZK] PASSAGE: Скарлетт суып сала берді де, оның жан дүниесінде өкініш пайда болды. TRANS: Skarlett suyp sala berdı de, onyñ jan düniesınde ökınış paida boldy. TRANSLATION: Scarlett grew cold, and remorse arose in her inner being.
A113: 110 | B113: Guilt — Felt guilt | C113: P2 | D113: felt guilt; child-like emotion; Ellen (internalized superego) | E113: There was more in the same vein but Scarlett did not finish it. For once, she was thoroughly frightened. She did not feel reckless and defiant now. She felt as young and guilty as when she was ten and had thrown a buttered biscuit at Suellen at the table. To think of her gentle mother reproving her so harshly and her father coming to town to talk to Captain Butler. The real seriousness of the matter grew on her. Gerald was going to be severe. This was one time when she knew she couldn't wiggle out of her punishment by sitting on his knee and being sweet and pert. | F113: Scarlett | G113: felt | H113: TERM: provinivshiysya (провинившийся) — the one at fault; one who has done wrong (active part.) [ORD] (lemma: провиниться) PASSAGE: Она чувствовала себя словно провинившийся ребенок — совсем как в десять лет, когда как-то раз за столом запустила в Сьюлин печеньем. TRANS: Ona chuvstvovala sebya slovno provinivshiysya rebenok — sovsem kak v desyat' let, kogda kak-to raz za stolom zapustila v S'yulin pechen'em. TRANSLATION: She felt as though she were a guilty child — exactly as at age ten, when she once threw a cookie at Suellen at the table. | I113: TERM: JAZYQTY (ЖАЗЫҚТЫ) — at fault; guilty [KED, SZK] PASSAGE: Сьюлинге тоқаш лақтырған кездегі жазықты болған он жасар жасөспірім кезіндегідей сезінді. TRANS: S'iulinge toqaş laqtyrğan kezdegı jazyqty bolğan on jasar jasöspırım kezındegıdei sezındı. TRANSLATION: She felt as if she were a ten-year-old who had thrown a roll at Suellen — like a guilty youngster.
A114: 111 | B114: Guilt — Felt guilt | C114: P2 | D114: felt guilt mixed with panic; fear of discovery | E114: "Mother of God!" thought Scarlett, in a panic of guilt. "'Concealing his real thoughts.' Can Melly have read his mind? Or my mind? Does she suspect that he and I—" | F114: Scarlett | G114: felt | H114: TERM: sovest' (совесть) — conscience; the inner moral faculty [ORD] PASSAGE: в испуге подумала Скарлетт, так как, совесть ее, разумеется, была нечиста. TRANS: v ispuge podumala Skarlett, tak kak, sovest' ee, razumeetsya, byla nechista. TRANSLATION: Scarlett thought in fright, since her conscience was, of course, not clean. | I114: TERM: AR-OJDAN (АР-ОЖДАН) — conscience (compound from Arabic wijdān): the inalienable inner tribunal [KED, SZK] PASSAGE: ... осылай ойлаған Скарлетт шошып кетті, өйткені оның ар-ұжданы, әрине, таза емес еді. TRANS: ... osylai oilağan Skarlett şoşyp kettı, öitkenı onyñ ar-ūjdany, ärine, taza emes edı. TRANSLATION: ... thinking thus, Scarlett took fright, for her ar-ujdan [conscience] was, of course, not clean.
A115: 112 | B115: Guilt — Felt guilt | C115: P2 | D115: felt guilt; inner moral accusation; Ellen (internalized superego); pain at deceiving her mother and abusing her trust, not at the actual misdeeds | E115: "I'm always your little girl," Scarlett would say and bury her head upon Ellen's breast, her guilt rising up to accuse her. She did not tell her mother that it was the dancing and the beaux which drew her back to Atlanta and not the service of the Confederacy. There were many things she kept from her mother these days. But, most of all, she kept secret the fact that Rhett Butler called frequently at Aunt Pittypat's house. | F115: Scarlett | G115: felt | H115: TERM: ugryzeniya sovesti. (угрызения совести.) = pangs of conscience PASSAGE: — Я всегда, всегда буду вашей маленькой дочуркой, — говорила Скарлетт и прятала лицо на груди Эллин, чувствуя внезапно вспыхнувшие угрызения совести. TRANS: — Ya vsegda, vsegda budu vashey malen'koy dochurkoy, — govorila Skarlett i pryatala litso na grudi Ellin, chuvstvuya vnezapno vspykhnuvshie ugryzeniya sovesti. TRANSLATION: "I will always, always be your little daughter," said Scarlett, hiding her face on Ellen's breast, feeling suddenly flaring pangs of conscience. | I115: TERM: QYSYLU (ҚЫСЫЛУ) — to feel embarrassed; to feel constrained; to be in difficulty [KED, SZK] PASSAGE: - Мен әрқашан сенің кішкентай қызың боламын, - деді Скарлетт өзінің ұжданы алдында қысылған жүзін Эллиннің кеудесіне жасырып. TRANS: Men ärqaşan senıñ kışkentai qyzyñ bolamyn, - dedı Skarlett özınıñ ūjdany aldynda qysylğan jüzın Elinnıñ keudesıne jasyryp. TRANSLATION: "I will always be your little girl," said Scarlett, hiding her face — embarrassed before her own conscience [ūjdan] — on Ellen's breast.
A116: 113 | B116: Guilt — Felt guilt (guilty conscience) | C116: P2 | D116: guilty conscience — guilt and conscience fused | E116: Scarlett's guilty conscience stirred as she tried to recall what Ashley might have written that would lead Melanie to make such a statement, but most of the letters she had read had gone out of her head as soon as she finished reading them. She believed Melanie had simply taken leave of her senses. | F116: Scarlett | G116: felt | H116: TERM: sovesti (совести) — conscience (gen./dat./prep.) [ORD] (lemma: совесть) PASSAGE: Скарлетт, испытывая легкий укол совести, старалась вспомнить, что же было такого в письмах Эшли, что заставило Мелани сделать подобное заявление, но содержание писем почти мгновенно улетучивалось у нее из головы, как только она кончала читать. TRANS: Skarlett, ispytyvaya legkiy ukol sovesti, staralas' vspomnit', chto zhe bylo takogo v pis'makh Eshli, chto zastavilo Melani sdelat' podobnoe zayavlenie, no soderzhanie pisem pochti mgnovenno uletuchivalos' u nee iz golovy, kak tol'ko ona konchala chitat'. TRANSLATION: Scarlett, feeling a slight prick of conscience, tried to recall what was in Ashley's letters that would make Melanie make such a statement, but the contents of the letters almost instantly evaporated from her head as soon as she finished reading. | I116: TERM: ūial- (ұял-) — be ashamed (verbal stem) [KED, SZK] (lemma: ұялу) PASSAGE: Скарлетт аздап ұялыс сезініп, Эшлидің хаттарындағы Меланиді осындай мәлімдеме жасауға итермелеген жолдарды еске түсіруге тырысты, ... TRANS: Skarlett azdap ūialys sezınıp, Eşlidıñ hattaryndağy Melanidı osyndai mälımdeme jasauğa itermelegen joldardy eske tüsıruge tyrysty, .... TRANSLATION: Feeling a slight twinge of shame, Scarlett tried to recall the lines in Ashley's letters that had pushed Melanie to make such a statement,...
A117: 114 | B117: Guilt — Guilt as tormentor | C117: P2 | D117: overwhelming felt guilt; inner moral accusation; no specific audience | E117: "Jealous—of me?" cried Scarlett, stricken with guilt. | F117: Scarlett | G117: felt | H117: TERM: sovesti (совести) — conscience (gen./dat./prep.) [ORD] (lemma: совесть) PASSAGE: — Завидуешь мне? — воскликнула Скарлетт, чувствуя легкий укол совести. TRANS: — Zaviduesh' mne? — voskliknula Skarlett, chuvstvuya legkiy ukol sovesti. TRANSLATION: "You're jealous of me?" exclaimed Scarlett, feeling a slight prick of conscience. | I117: TERM: AR-OJDAN (АР-ОЖДАН) — conscience (compound from Arabic wijdān): the inalienable inner tribunal [KED, SZK] PASSAGE: - Сен менен қызғанасың ба? - деп айқайлады Скарлетт ар-ұжданы ептеп мазалап. TRANS: - Sen menen qyzğanasyñ ba? - dep aiqailady Skarlett ar-ūjdany eptep mazalap. TRANSLATION: "Are you jealous of me?" — Scarlett cried out, her ar-ujdan [conscience] slightly troubling her.
...

Sheet Summary
A1: Gone with the Wind — moral-emotion corpus: counts
A2: Dual-character tokens (#23, #128, #229) are counted under each of their two characters; token totals count each token once via the Token column.
A4: Tokens by English word (domain)
A5: English word | B5: Tokens
A6: Shame | B6: =SUMIFS('Data (parsed)'!$I$2:$I$235,'Data (parsed)'!$B$2:$B$235,A6) -> 104
A7: Guilt | B7: =SUMIFS('Data (parsed)'!$I$2:$I$235,'Data (parsed)'!$B$2:$B$235,A7) -> 31
A8: Conscience | B8: =SUMIFS('Data (parsed)'!$I$2:$I$235,'Data (parsed)'!$B$2:$B$235,A8) -> 39
A9: Honor | B9: =SUMIFS('Data (parsed)'!$I$2:$I$235,'Data (parsed)'!$B$2:$B$235,A9) -> 57
A10: Total | B10: =SUM(B6:B9) -> 231
A12: Tokens by English word × Part of novel (the arc)
B13: P1 | C13: P2 | D13: P3 | E13: P4 | F13: P5 | G13: Total
A14: Shame | B14: =SUMIFS('Data (parsed)'!$I$2:$I$235,'Data (parsed)'!$B$2:$B$235,$A14,'Data (parsed)'!$D$2:$D$235,B$13) -> 6 | C14: =SUMIFS('Data (parsed)'!$I$2:$I$235,'Data (parsed)'!$B$2:$B$235,$A14,'Data (parsed)'!$D$2:$D$235,C$13) -> 14 | D14: =SUMIFS('Data (parsed)'!$I$2:$I$235,'Data (parsed)'!$B$2:$B$235,$A14,'Data (parsed)'!$D$2:$D$235,D$13) -> 17 | E14: =SUMIFS('Data (parsed)'!$I$2:$I$235,'Data (parsed)'!$B$2:$B$235,$A14,'Data (parsed)'!$D$2:$D$235,E$13) -> 37 | F14: =SUMIFS('Data (parsed)'!$I$2:$I$235,'Data (parsed)'!$B$2:$B$235,$A14,'Data (parsed)'!$D$2:$D$235,F$13) -> 30 | G14: =SUM(B14:F14) -> 104
A15: Guilt | B15: =SUMIFS('Data (parsed)'!$I$2:$I$235,'Data (parsed)'!$B$2:$B$235,$A15,'Data (parsed)'!$D$2:$D$235,B$13) -> 4 | C15: =SUMIFS('Data (parsed)'!$I$2:$I$235,'Data (parsed)'!$B$2:$B$235,$A15,'Data (parsed)'!$D$2:$D$235,C$13) -> 7 | D15: =SUMIFS('Data (parsed)'!$I$2:$I$235,'Data (parsed)'!$B$2:$B$235,$A15,'Data (parsed)'!$D$2:$D$235,D$13) -> 2 | E15: =SUMIFS('Data (parsed)'!$I$2:$I$235,'Data (parsed)'!$B$2:$B$235,$A15,'Data (parsed)'!$D$2:$D$235,E$13) -> 5 | F15: =SUMIFS('Data (parsed)'!$I$2:$I$235,'Data (parsed)'!$B$2:$B$235,$A15,'Data (parsed)'!$D$2:$D$235,F$13) -> 13 | G15: =SUM(B15:F15) -> 31
A16: Conscience | B16: =SUMIFS('Data (parsed)'!$I$2:$I$235,'Data (parsed)'!$B$2:$B$235,$A16,'Data (parsed)'!$D$2:$D$235,B$13) -> 3 | C16: =SUMIFS('Data (parsed)'!$I$2:$I$235,'Data (parsed)'!$B$2:$B$235,$A16,'Data (parsed)'!$D$2:$D$235,C$13) -> 6 | D16: =SUMIFS('Data (parsed)'!$I$2:$I$235,'Data (parsed)'!$B$2:$B$235,$A16,'Data (parsed)'!$D$2:$D$235,D$13) -> 5 | E16: =SUMIFS('Data (parsed)'!$I$2:$I$235,'Data (parsed)'!$B$2:$B$235,$A16,'Data (parsed)'!$D$2:$D$235,E$13) -> 17 | F16: =SUMIFS('Data (parsed)'!$I$2:$I$235,'Data (parsed)'!$B$2:$B$235,$A16,'Data (parsed)'!$D$2:$D$235,F$13) -> 8 | G16: =SUM(B16:F16) -> 39
A17: Honor | B17: =SUMIFS('Data (parsed)'!$I$2:$I$235,'Data (parsed)'!$B$2:$B$235,$A17,'Data (parsed)'!$D$2:$D$235,B$13) -> 6 | C17: =SUMIFS('Data (parsed)'!$I$2:$I$235,'Data (parsed)'!$B$2:$B$235,$A17,'Data (parsed)'!$D$2:$D$235,C$13) -> 5 | D17: =SUMIFS('Data (parsed)'!$I$2:$I$235,'Data (parsed)'!$B$2:$B$235,$A17,'Data (parsed)'!$D$2:$D$235,D$13) -> 2 | E17: =SUMIFS('Data (parsed)'!$I$2:$I$235,'Data (parsed)'!$B$2:$B$235,$A17,'Data (parsed)'!$D$2:$D$235,E$13) -> 31 | F17: =SUMIFS('Data (parsed)'!$I$2:$I$235,'Data (parsed)'!$B$2:$B$235,$A17,'Data (parsed)'!$D$2:$D$235,F$13) -> 13 | G17: =SUM(B17:F17) -> 57
A18: Total | B18: =SUM(B14:B17) -> 19 | C18: =SUM(C14:C17) -> 32 | D18: =SUM(D14:D17) -> 26 | E18: =SUM(E14:E17) -> 90 | F18: =SUM(F14:F17) -> 64 | G18: =SUM(G14:G17) -> 231
A20: Tokens by character × English word (dual tokens counted under each character)
A21: Character | B21: Shame | C21: Guilt | D21: Conscience | E21: Honor | F21: Total
A22: Scarlett | B22: =COUNTIFS('Data (parsed)'!$E$2:$E$235,$A22,'Data (parsed)'!$B$2:$B$235,B$21) -> 48 | C22: =COUNTIFS('Data (parsed)'!$E$2:$E$235,$A22,'Data (parsed)'!$B$2:$B$235,C$21) -> 24 | D22: =COUNTIFS('Data (parsed)'!$E$2:$E$235,$A22,'Data (parsed)'!$B$2:$B$235,D$21) -> 31 | E22: =COUNTIFS('Data (parsed)'!$E$2:$E$235,$A22,'Data (parsed)'!$B$2:$B$235,E$21) -> 9 | F22: =SUM(B22:E22) -> 112
A23: Ashley | B23: =COUNTIFS('Data (parsed)'!$E$2:$E$235,$A23,'Data (parsed)'!$B$2:$B$235,B$21) -> 7 | C23: =COUNTIFS('Data (parsed)'!$E$2:$E$235,$A23,'Data (parsed)'!$B$2:$B$235,C$21) -> 0 | D23: =COUNTIFS('Data (parsed)'!$E$2:$E$235,$A23,'Data (parsed)'!$B$2:$B$235,D$21) -> 0 | E23: =COUNTIFS('Data (parsed)'!$E$2:$E$235,$A23,'Data (parsed)'!$B$2:$B$235,E$21) -> 28 | F23: =SUM(B23:E23) -> 35
A24: Rhett | B24: =COUNTIFS('Data (parsed)'!$E$2:$E$235,$A24,'Data (parsed)'!$B$2:$B$235,B$21) -> 20 | C24: =COUNTIFS('Data (parsed)'!$E$2:$E$235,$A24,'Data (parsed)'!$B$2:$B$235,C$21) -> 0 | D24: =COUNTIFS('Data (parsed)'!$E$2:$E$235,$A24,'Data (parsed)'!$B$2:$B$235,D$21) -> 2 | E24: =COUNTIFS('Data (parsed)'!$E$2:$E$235,$A24,'Data (parsed)'!$B$2:$B$235,E$21) -> 8 | F24: =SUM(B24:E24) -> 30
A25: Melanie | B25: =COUNTIFS('Data (parsed)'!$E$2:$E$235,$A25,'Data (parsed)'!$B$2:$B$235,B$21) -> 8 | C25: =COUNTIFS('Data (parsed)'!$E$2:$E$235,$A25,'Data (parsed)'!$B$2:$B$235,C$21) -> 3 | D25: =COUNTIFS('Data (parsed)'!$E$2:$E$235,$A25,'Data (parsed)'!$B$2:$B$235,D$21) -> 1 | E25: =COUNTIFS('Data (parsed)'!$E$2:$E$235,$A25,'Data (parsed)'!$B$2:$B$235,E$21) -> 1 | F25: =SUM(B25:E25) -> 13
A26: Community / South | B26: =COUNTIFS('Data (parsed)'!$E$2:$E$235,$A26,'Data (parsed)'!$B$2:$B$235,B$21) -> 4 | C26: =COUNTIFS('Data (parsed)'!$E$2:$E$235,$A26,'Data (parsed)'!$B$2:$B$235,C$21) -> 0 | D26: =COUNTIFS('Data (parsed)'!$E$2:$E$235,$A26,'Data (parsed)'!$B$2:$B$235,D$21) -> 0 | E26: =COUNTIFS('Data (parsed)'!$E$2:$E$235,$A26,'Data (parsed)'!$B$2:$B$235,E$21) -> 9 | F26: =SUM(B26:E26) -> 13
A27: Frank Kennedy | B27: =COUNTIFS('Data (parsed)'!$E$2:$E$235,$A27,'Data (parsed)'!$B$2:$B$235,B$21) -> 3 | C27: =COUNTIFS('Data (parsed)'!$E$2:$E$235,$A27,'Data (parsed)'!$B$2:$B$235,C$21) -> 0 | D27: =COUNTIFS('Data (parsed)'!$E$2:$E$235,$A27,'Data (parsed)'!$B$2:$B$235,D$21) -> 2 | E27: =COUNTIFS('Data (parsed)'!$E$2:$E$235,$A27,'Data (parsed)'!$B$2:$B$235,E$21) -> 0 | F27: =SUM(B27:E27) -> 5
A28: Rene Picard | B28: =COUNTIFS('Data (parsed)'!$E$2:$E$235,$A28,'Data (parsed)'!$B$2:$B$235,B$21) -> 3 | C28: =COUNTIFS('Data (parsed)'!$E$2:$E$235,$A28,'Data (parsed)'!$B$2:$B$235,C$21) -> 0 | D28: =COUNTIFS('Data (parsed)'!$E$2:$E$235,$A28,'Data (parsed)'!$B$2:$B$235,D$21) -> 0 | E28: =COUNTIFS('Data (parsed)'!$E$2:$E$235,$A28,'Data (parsed)'!$B$2:$B$235,E$21) -> 0 | F28: =SUM(B28:E28) -> 3
A29: Gerald O’Hara | B29: =COUNTIFS('Data (parsed)'!$E$2:$E$235,$A29,'Data (parsed)'!$B$2:$B$235,B$21) -> 0 | C29: =COUNTIFS('Data (parsed)'!$E$2:$E$235,$A29,'Data (parsed)'!$B$2:$B$235,C$21) -> 2 | D29: =COUNTIFS('Data (parsed)'!$E$2:$E$235,$A29,'Data (parsed)'!$B$2:$B$235,D$21) -> 1 | E29: =COUNTIFS('Data (parsed)'!$E$2:$E$235,$A29,'Data (parsed)'!$B$2:$B$235,E$21) -> 0 | F29: =SUM(B29:E29) -> 3
A30: Uncle Peter | B30: =COUNTIFS('Data (parsed)'!$E$2:$E$235,$A30,'Data (parsed)'!$B$2:$B$235,B$21) -> 2 | C30: =COUNTIFS('Data (parsed)'!$E$2:$E$235,$A30,'Data (parsed)'!$B$2:$B$235,C$21) -> 0 | D30: =COUNTIFS('Data (parsed)'!$E$2:$E$235,$A30,'Data (parsed)'!$B$2:$B$235,D$21) -> 0 | E30: =COUNTIFS('Data (parsed)'!$E$2:$E$235,$A30,'Data (parsed)'!$B$2:$B$235,E$21) -> 0 | F30: =SUM(B30:E30) -> 2
A31: Mammy | B31: =COUNTIFS('Data (parsed)'!$E$2:$E$235,$A31,'Data (parsed)'!$B$2:$B$235,B$21) -> 1 | C31: =COUNTIFS('Data (parsed)'!$E$2:$E$235,$A31,'Data (parsed)'!$B$2:$B$235,C$21) -> 0 | D31: =COUNTIFS('Data (parsed)'!$E$2:$E$235,$A31,'Data (parsed)'!$B$2:$B$235,D$21) -> 1 | E31: =COUNTIFS('Data (parsed)'!$E$2:$E$235,$A31,'Data (parsed)'!$B$2:$B$235,E$21) -> 0 | F31: =SUM(B31:E31) -> 2
A32: Suellen | B32: =COUNTIFS('Data (parsed)'!$E$2:$E$235,$A32,'Data (parsed)'!$B$2:$B$235,B$21) -> 2 | C32: =COUNTIFS('Data (parsed)'!$E$2:$E$235,$A32,'Data (parsed)'!$B$2:$B$235,C$21) -> 0 | D32: =COUNTIFS('Data (parsed)'!$E$2:$E$235,$A32,'Data (parsed)'!$B$2:$B$235,D$21) -> 0 | E32: =COUNTIFS('Data (parsed)'!$E$2:$E$235,$A32,'Data (parsed)'!$B$2:$B$235,E$21) -> 0 | F32: =SUM(B32:E32) -> 2
A33: Prissy | B33: =COUNTIFS('Data (parsed)'!$E$2:$E$235,$A33,'Data (parsed)'!$B$2:$B$235,B$21) -> 1 | C33: =COUNTIFS('Data (parsed)'!$E$2:$E$235,$A33,'Data (parsed)'!$B$2:$B$235,C$21) -> 0 | D33: =COUNTIFS('Data (parsed)'!$E$2:$E$235,$A33,'Data (parsed)'!$B$2:$B$235,D$21) -> 0 | E33: =COUNTIFS('Data (parsed)'!$E$2:$E$235,$A33,'Data (parsed)'!$B$2:$B$235,E$21) -> 0 | F33: =SUM(B33:E33) -> 1
